File: 50K.DAT
[Header]
; VSM Data File (default extension .dat)
; Copyright (c) 2003-2013, Quantum Design, Inc. All rights reserved.
TITLE,
FILEOPENTIME,3895749970.01412,06/12/2023,4:46 pm
BYAPP,VSM,1.0,1.0
INFO,DYNACOOL VSM Option Release 1.4.10 Build 1,APPNAME
INFO,Quantum Design Linear Motor Servo Controller,MOTOR_MODULE_NAME
INFO,3101-100 N2,MOTOR_HW_VERSION
INFO,MMC1154,MOTOR_SERIAL_NUMBER
INFO,SRV No X-over 01.03.11,MOTOR_SOFTWARE_VERSION
INFO,Quantum Design VSM Detection Module,VSM_MODULE_NAME
INFO,3101-150 F0,VSM_HW_VERSION
INFO,VSM783,VSM_SERIAL_NUMBER
INFO,VSM No X-over 01.02.05 May 20 2008 13:51:47,VSM_SOFTWARE_VERSION
INFO,771,PREAMP_SERIAL_NUMBER
INFO,906,COIL_SERIAL_NUMBER
INFO,0,MOMENT_UNITS
INFO,MoS2,SAMPLE_MATERIAL
INFO,First Batch 2022,SAMPLE_COMMENT
INFO,,SAMPLE_MASS
INFO,,SAMPLE_VOLUME
INFO,,SAMPLE_MOLECULAR_WEIGHT
INFO,,SAMPLE_SIZE
INFO,,SAMPLE_SHAPE
DATATYPE,COMMENT,1
DATATYPE,TIME,2
STARTUPAXIS,X,2
STARTUPAXIS,Y1,5
[Data]
Comment,Time Stamp (sec),Temperature (K),Magnetic Field (Oe),Moment (emu),M. Std. Err. (emu),Transport Action,Averaging Time (sec),Frequency (Hz),Peak Amplitude (mm),Center Position (mm),Coil Signal' (mV),Coil Signal" (mV),Range (mV),M. Quad. Signal (emu),M. Raw' (emu),M. Raw" (emu),Min. Temperature (K),Max. Temperature (K),Min. Field (Oe),Max. Field (Oe),Mass (grams),Motor Lag (deg),Pressure (Torr),VSM Status (code),Motor Status (code),Measure Status (code),Measure Count,System Temp. (K),Temp. Status (code),Field Status (code),Chamber Status (code),Motor Current (amps),Motor Heatsink Temp. (C),Map 01,Map 02,Map 03,Map 04,Map 05,Map 06,Map 07,Map 08,Map 09,Map 10,Map 11,Map 12,Map 13,Map 14,Map 15,Map 16
,3895749996.866,49.7840985281982,3000.02807617188,,,2,,,,17.7779997499585,,,,,,,49.7840985281982,49.7840985281982,3000.02807617188,3000.02807617188,,,0.998387932777405,,,,,50.4672088623047,0,0,0,0.03814697265625,33.2355842590332,,,,,,,,,,,,,,,,
,3895750023.2395,49.7940826416016,2898.1962890625,-2.34391522581575E-5,3.7353390543307E-7,1,0.499626677034896,40.0298881530762,1.99564697507985,17.7599992603064,-0.000243092162013296,-6.83403605517397E-5,0.25,-2.20408188794776E-6,-2.33845563916639E-5,-2.37466519243866E-6,49.7940254211426,49.7940254211426,2895.68920898438,2900.70336914063,52.0963224352555,20.3730478530703,0.997936844825745,0,0,0,20,50.4887771606445,1,6,3,2.22976684570313,37.1456527709961,,,,,,,,,,,,,,,,
,3895750034.82,49.8014526367188,2782.16455078125,-2.17118505696424E-5,3.15043992758175E-7,1,0.499626677034896,40.0298881530762,1.99566047619897,17.7599992603064,-0.000224772868567253,-6.55315215760804E-5,0.25,-2.25271756594473E-6,-2.16596513228372E-5,-2.41037840158914E-6,49.8014526367188,49.8014526367188,2780.6396484375,2783.689453125,51.8055566261016,20.3738458402923,0.997859418392181,0,0,0,20,50.4974746704102,1,6,3,2.22335815429687,38.1231689453125,,,,,,,,,,,,,,,,
,3895750046.215,49.8068904876709,2668.2412109375,-2.05794857012844E-5,3.00166724346562E-7,1,0.499626677034896,40.0298881530762,1.99568716502772,17.7599992603064,-0.000212530757434263,-6.49743747403295E-5,0.25,-2.40626333964931E-6,-2.05279299203586E-5,-2.55524956028546E-6,49.8067779541016,49.8067779541016,2665.71069335938,2670.77172851562,51.7750731138516,20.3755747439047,0.99771386384964,0,0,0,20,50.5037841796875,1,6,3,2.21755981445313,42.0332374572754,,,,,,,,,,,,,,,,
,3895750057.7145,49.8105049133301,2553.30859375,-1.89816959486095E-5,2.47856714776897E-7,1,0.499626677034896,40.0298881530762,1.99560696523639,17.7599992603064,-0.000197307538156471,-5.28723961044726E-5,0.25,-1.55084885804566E-6,-1.89390404808431E-5,-1.68935419243803E-6,49.810474395752,49.810474395752,2550.84985351562,2555.76733398438,52.0525512381786,20.3769246847902,0.997376143932343,0,0,0,20,50.5124816894531,1,6,3,2.21908569335938,39.5894432067871,,,,,,,,,,,,,,,,
,3895750069.196,49.8166999816895,2438.35083007813,-1.72149462138154E-5,3.07000336277796E-7,1,0.499626677034896,40.0298881530762,1.99570377241678,17.7599992603064,-0.000177892058581145,-5.37608892304733E-5,0.25,-1.95686787236432E-6,-1.71721217672127E-5,-2.08157200342766E-6,49.8166999816895,49.8166999816895,2435.85131835938,2440.85034179687,51.7453712301209,20.3741454130449,0.997426807880402,0,0,0,20,50.5203323364258,1,6,3,2.22122192382813,39.1006851196289,,,,,,,,,,,,,,,,
,3895750080.677,49.8217124938965,2323.05224609375,-1.54398619356945E-5,3.27650874304948E-7,1,0.499626677034896,40.0298881530762,1.99572139912056,17.7599992603064,-0.000159573747804895,-4.80869475212609E-5,0.25,-1.74269978812986E-6,-1.54014956715023E-5,-1.85455869449341E-6,49.8213844299316,49.8213844299316,2320.52612304687,2325.57836914062,52.0142514407363,20.3777981740946,0.997133731842041,0,0,0,20,50.5281219482422,1,6,3,2.22320556640625,40.0782012939453,,,,,,,,,,,,,,,,
,3895750092.179,49.8291320800781,2208.57055664062,-1.43316115428285E-5,3.15604574263503E-7,1,0.499626677034896,40.0298881530762,1.99572642622688,17.7599992603064,-0.000148146189502479,-4.44904734586474E-5,0.25,-1.60388372833332E-6,-1.42960669700445E-5,-1.70773139863441E-6,49.8290061950684,49.8290061950684,2206.60180664062,2210.53930664062,51.7344284308516,20.3812038211069,0.99712198972702,0,0,0,20,50.5349884033203,1,6,3,2.22427368164062,41.5444793701172,,,,,,,,,,,,,,,,
,3895750103.662,49.8349437713623,2093.21252441406,-1.28580210504079E-5,3.50740519387149E-7,1,0.499626677034896,40.0298881530762,1.99563510887194,17.7599992603064,-0.000132163412671903,-4.39959360960248E-5,0.25,-1.82581435702003E-6,-1.28232198390652E-5,-1.91834027744125E-6,49.8347587585449,49.8347587585449,2090.728515625,2095.69653320313,51.8751215643132,20.3805348591292,0.996998429298401,0,0,0,20,50.5436401367188,1,6,3,2.22381591796875,41.055721282959,,,,,,,,,,,,,,,,
,3895750115.151,49.8404407501221,1978.65277099609,-1.09515486664486E-5,3.29714851618605E-7,1,0.499626677034896,40.0298881530762,1.99557700856202,17.7599992603064,-0.000112760979632777,-3.63904541973238E-5,0.25,-1.45264891238792E-6,-1.09226371159538E-5,-1.53162001093956E-6,49.8404808044434,49.8404808044434,1976.61560058594,1980.68994140625,51.9947107277555,20.3798383233034,0.996998369693756,0,0,0,20,50.547046661377,1,6,3,2.22000122070313,41.5444793701172,,,,,,,,,,,,,,,,
,3895750126.66,49.8456764221191,1863.65447998047,-9.62998113691723E-6,2.99716377251919E-7,1,0.499626677034896,40.0298881530762,1.99558277164505,17.7599992603064,-9.78728966866447E-5,-3.90254614757981E-5,0.25,-1.94326953350813E-6,-9.59958225497563E-6,-2.01160267855993E-6,49.8456230163574,49.8456230163574,1861.64819335938,1865.66076660156,51.7445896016016,20.3798316214982,0.996895670890808,0,0,0,20,50.5518493652344,1,6,3,2.22000122070313,40.5669593811035,,,,,,,,,,,,,,,,
,3895750138.143,49.8503589630127,1749.27795410156,-8.49754669718881E-6,2.95053762574978E-7,1,0.499626677034896,40.0298881530762,1.99560705100823,17.7599992603064,-8.6849864856984E-5,-3.17727333879133E-5,0.25,-1.46229246432959E-6,-8.47257274154458E-6,-1.52300321165624E-6,49.8502807617188,49.8502807617188,1746.73120117187,1751.82470703125,51.8133729112939,20.3794868558675,0.996679425239563,0,0,0,20,50.5590972900391,1,6,3,2.23175048828125,41.055721282959,,,,,,,,,,,,,,,,
,3895750149.6375,49.855598449707,1633.81195068359,-7.19963104789345E-6,4.13715495436365E-7,1,0.499626677034896,40.0298881530762,1.99564209139996,17.7599992603064,-7.42144559321717E-5,-2.34692502786093E-5,0.25,-9.11896257653147E-7,-7.18088122808922E-6,-9.63873855707274E-7,49.8553733825684,49.8553733825684,1631.79895019531,1635.82495117187,51.7750731138516,20.3787845322266,0.996561348438263,0,0,0,20,50.564811706543,1,6,3,2.2320556640625,40.5669593811035,,,,,,,,,,,,,,,,
,3895750161.136,49.861909866333,1519.53961181641,-5.12979373812584E-6,3.46102876779418E-7,1,0.499626677034896,40.0298881530762,1.99554760773091,17.7599992603064,-5.17220864360894E-5,-2.30510374816801E-5,0.25,-1.24964774269871E-6,-5.11196467012265E-6,-1.28568106013624E-6,49.8617782592773,49.8617782592773,1517.08203125,1521.99719238281,51.9399967314093,20.381831517755,0.996382594108582,0,0,0,20,50.5690078735352,1,6,3,2.23098754882813,40.5669593811035,,,,,,,,,,,,,,,,
,3895750172.621,49.8664855957031,1404.52593994141,-3.89778947111468E-6,3.6285560362222E-7,1,0.499626677034896,40.0298881530762,1.9955497419528,17.7599992603064,-3.97522886452126E-5,-1.50341467075385E-5,0.25,-7.14406404321101E-7,-3.8859780179265E-6,-7.42174920133156E-7,49.8664855957031,49.8664855957031,1402.01403808594,1407.03784179688,52.054114495217,20.3817704123027,0.996290266513825,0,0,0,20,50.575382232666,1,6,3,2.22152709960938,40.0782012939453,,,,,,,,,,,,,,,,
,3895750184.109,49.8713893890381,1289.59020996094,-3.01941807144241E-6,4.294196475113E-7,1,0.499626677034896,40.0298881530762,1.99554685913876,17.7599992603064,-2.99157881668093E-5,-1.64638336744762E-5,0.25,-1.01001915484791E-6,-3.00686761307142E-6,-1.0307651530488E-6,49.871208190918,49.871208190918,1287.11352539062,1292.06689453125,52.3480068184478,20.3839061617634,0.996105313301086,0,0,0,20,50.5804862976074,1,6,3,2.222900390625,41.5444793701172,,,,,,,,,,,,,,,,
,3895750195.5995,49.8764877319336,1174.65057373047,-1.8543116544879E-6,3.84464515507883E-7,1,0.499626677034896,40.0298881530762,1.99547408078262,17.7599992603064,-1.77461612900654E-5,-1.3541037193581E-5,0.25,-9.45425424418806E-7,-1.84418353631935E-6,-9.57620151811302E-7,49.8763389587402,49.8763389587402,1172.1220703125,1177.17907714844,52.1244610619478,20.3837953230315,0.99617213010788,0,0,0,20,50.5861282348633,1,6,3,2.222900390625,43.0107536315918,,,,,,,,,,,,,,,,
,3895750207.0925,49.8826637268066,1059.63806152344,-7.78241137343796E-7,3.00995732095093E-7,1,0.499626677034896,40.0298881530762,1.99555625833086,17.7599992603064,-5.98572803583071E-6,-1.37067663880158E-5,0.25,-1.15722636125651E-6,-7.68338905717954E-7,-1.1610689931455E-6,49.8826141357422,49.8826141357422,1057.19311523438,1062.0830078125,51.9493762736401,20.381173288395,0.996044933795929,0,0,0,20,50.5895805358887,1,6,3,2.21786499023438,42.5219955444336,,,,,,,,,,,,,,,,
,3895750218.5695,49.8874111175537,944.722473144531,2.17532066485935E-7,2.13483533697498E-7,1,0.499626677034896,40.0298881530762,1.99562837908979,17.7599992603064,3.15354284291656E-6,-4.29021467423605E-6,0.25,-4.46249705020558E-7,2.20482421162644E-7,-4.43884469881901E-7,49.8873252868652,49.8873252868652,942.227233886719,947.217712402344,51.8954439058132,20.3818918466047,0.995950937271118,0,0,0,20,50.5923767089844,1,6,3,2.2222900390625,42.5219955444336,,,,,,,,,,,,,,,,
,3895750230.0855,49.8906517028809,829.823913574219,1.40033936905749E-6,1.66524161070996E-7,1,0.499626677034896,40.0298881530762,1.99556551736466,17.7599992603064,1.66266893535786E-5,-7.46480139238574E-6,0.25,-9.62736771495091E-7,1.40513750967524E-6,-9.50714054358566E-7,49.8908195495605,49.8908195495605,827.38427734375,832.263549804687,52.0838163789478,20.3847386085953,0.995719909667969,0,0,0,20,50.5961608886719,1,6,3,2.22976684570313,41.5444793701172,,,,,,,,,,,,,,,,
,3895750241.5655,49.8944644927978,714.905670166016,2.51250558470441E-6,2.25325079424718E-7,1,0.499626677034896,40.0298881530762,1.99557742194026,17.7599992603064,2.80856145336183E-5,-3.81302787525586E-6,0.25,-8.19353103322677E-7,2.51436173913524E-6,-7.99306611416031E-7,49.8944091796875,49.8944091796875,712.893981933594,716.917358398438,51.7406814590055,20.3829758141622,0.995573461055756,0,0,0,20,50.6014747619629,1,6,3,2.23007202148438,41.055721282959,,,,,,,,,,,,,,,,
,3895750253.0435,49.8992538452148,600.027587890625,3.0112437207469E-6,2.90219573351434E-7,1,0.499626677034896,40.0298881530762,1.99560784533593,17.7599992603064,3.30075655763287E-5,-9.84607202673023E-7,0.25,-6.42191945877916E-7,3.01093709560249E-6,-6.18737236124811E-7,49.8992538452148,49.8992538452148,598.043151855469,602.012023925781,51.8727766787555,20.3826439615492,0.99544757604599,0,0,0,20,50.6053466796875,1,6,3,2.22122192382813,42.0332374572754,,,,,,,,,,,,,,,,
,3895750264.559,49.9037170410156,484.458557128906,3.4302290217058E-6,2.32340261731712E-7,1,0.499626677034896,40.0298881530762,1.99554564329936,17.7599992603064,3.758468447308E-5,-1.04279978750505E-6,0.25,-7.2408083578496E-7,3.42981674164212E-6,-6.97373886127423E-7,49.9037170410156,49.9037170410156,481.997314453125,486.919799804687,51.5444927006785,20.3829277901901,0.995443344116211,0,0,0,20,50.6082305908203,1,6,3,2.22686767578125,42.5219955444336,,,,,,,,,,,,,,,,
,3895750276.058,49.9059619903564,370.045700073242,4.2536062155291E-6,3.32369281951318E-7,1,0.499626677034896,40.0298881530762,1.99556565899944,17.7599992603064,4.59849928260588E-5,2.11753366910422E-6,0.25,-5.74632351853455E-7,4.25068197101182E-6,-5.42059415743322E-7,49.9058952331543,49.9058952331543,368.055755615234,372.03564453125,51.9181111328709,20.3839830956164,0.99526834487915,0,0,0,20,50.611644744873,1,6,3,2.21725463867187,42.0332374572754,,,,,,,,,,,,,,,,
,3895750287.5875,49.9104080200195,255.102363586426,4.05777716926811E-6,3.26048462885863E-7,1,0.499626677034896,40.0298881530762,1.99550782119492,17.7599992603064,4.41194754332457E-5,6.32780493164202E-7,0.25,-6.79656948981131E-7,4.05595704367898E-6,-6.48360292834881E-7,49.9100227355957,49.9100227355957,252.06623840332,258.138488769531,51.6343799803901,20.3830318719786,0.995054662227631,0,0,0,20,50.6159629821777,1,6,3,2.22213745117187,43.9882698059082,,,,,,,,,,,,,,,,
,3895750299.0255,49.9134750366211,140.674911499023,4.61232260361351E-6,3.37776776946522E-7,1,0.499626677034896,40.0298881530762,1.99562677912109,17.7599992603064,4.90002875534801E-5,7.03626634114891E-6,0.25,-1.73848403713629E-7,4.6057970162719E-6,-1.39288164544189E-7,49.9134521484375,49.9134521484375,138.177383422852,143.172439575195,52.0713103226401,20.3854432875503,0.995014369487762,0,0,0,20,50.6175651550293,1,6,3,2.22915649414062,42.5219955444336,,,,,,,,,,,,,,,,
,3895750310.5165,49.9164180755615,25.6013641357422,4.18128361865149E-6,3.23471073222185E-7,1,0.499626677034896,40.0298881530762,1.99557508503309,17.7599992603064,4.55447862757901E-5,2.06929770558149E-7,0.25,-7.42531596029597E-7,4.17970712912116E-6,-7.102088838935E-7,49.9161834716797,49.9161834716797,23.0969734191895,28.1057548522949,52.148691546044,20.3830409084273,0.994938373565674,0,0,0,20,50.6215019226074,1,6,3,2.218017578125,43.9882698059082,,,,,,,,,,,,,,,,
,3895750322.002,49.9196071624756,-89.2839698791504,2.82946576319545E-6,3.47882169769765E-7,1,0.499626677034896,40.0298881530762,1.9955642221972,17.7599992603064,3.05057063021211E-5,1.86414383074083E-6,0.25,-3.39061622695167E-7,2.82719140165378E-6,-3.17466651343319E-7,49.9194297790527,49.9194297790527,-91.7907333374023,-86.7772064208984,51.8555808513324,20.3828500837504,0.994779944419861,0,0,0,20,50.6257553100586,1,6,3,2.22320556640625,40.0782012939453,,,,,,,,,,,,,,,,
,3895750333.4965,49.9219131469727,-204.403076171875,9.23058699736487E-7,3.12756748058919E-7,1,0.499626677034896,40.0298881530762,1.99561080868638,17.7599992603064,1.03421017599841E-5,-1.53116510825505E-6,0.25,-3.13367709531992E-7,9.238262760994E-7,-3.05980263593726E-7,49.9215965270996,49.9215965270996,-206.934448242187,-201.871704101562,52.2737521091209,20.3813399059439,0.994728744029999,0,0,0,20,50.6277656555176,1,6,3,2.21786499023438,43.0107536315918,,,,,,,,,,,,,,,,
,3895750344.9795,49.9254283905029,-319.276885986328,1.69252166374512E-7,2.37889004024638E-7,1,0.499626677034896,40.0298881530762,1.99554790296214,17.7599992603064,2.60956806999545E-6,-4.19399205034939E-6,0.25,-4.28348546487806E-7,1.72149121217527E-7,-4.26368728476217E-7,49.9255523681641,49.9255523681641,-321.753509521484,-316.800262451172,52.301109107294,20.38128432366,0.994435906410217,0,0,0,20,50.631103515625,1,6,3,2.2283935546875,43.9882698059082,,,,,,,,,,,,,,,,
,3895750356.4805,49.9293613433838,-434.338394165039,1.07269947583416E-7,3.27894938073713E-7,1,0.499626677034896,40.0298881530762,1.99557140628093,17.7599992603064,1.1597224634641E-6,5.32272670140114E-8,0.25,-1.45079905082655E-8,1.07197323417974E-7,-1.36866201207407E-8,49.9293746948242,49.9293746948242,-436.897735595703,-431.779052734375,52.047079838544,20.3836607112426,0.994454562664032,0,0,0,20,50.6345100402832,1,6,3,2.22030639648438,42.5219955444336,,,,,,,,,,,,,,,,
,3895750367.977,49.9324111938477,-548.767761230469,-2.53722477863008E-7,2.391930332017E-7,1,0.499626677034896,40.0298881530762,1.99556939507796,17.7599992603064,-2.20849057729752E-6,-3.05869087026637E-6,0.25,-2.43643494257275E-7,-2.51486677776651E-7,-2.45119889182734E-7,49.9323425292969,49.9323425292969,-550.836669921875,-546.698852539063,52.0330105251978,20.3825520887908,0.994346082210541,0,0,0,20,50.6349334716797,1,6,3,2.220458984375,43.9882698059082,,,,,,,,,,,,,,,,
,3895750379.4515,49.9334964752197,-663.247222900391,2.34760668828537E-8,2.55894183320044E-7,1,0.499626677034896,40.0298881530762,1.99553400261285,17.7599992603064,-6.91885124644509E-8,1.78364445765796E-6,0.25,1.64770022961331E-7,2.2212565756288E-8,1.64668712448685E-7,49.9334144592285,49.9334144592285,-665.731750488281,-660.7626953125,51.6765879204285,20.3851040572838,0.994190275669098,0,0,0,20,50.638011932373,1,6,3,2.20443725585938,42.5219955444336,,,,,,,,,,,,,,,,
,3895750390.969,49.9372730255127,-778.197021484375,-9.47471822237503E-8,2.04234027983855E-7,1,0.499626677034896,40.0298881530762,1.99543372604759,17.7599992603064,-9.7176463483815E-7,-3.35129875531152E-7,0.25,-1.44939809305309E-8,-9.44814072158E-8,-1.51737689255905E-8,49.9371948242188,49.9371948242188,-780.7119140625,-775.68212890625,51.8532359657747,20.3821116262812,0.994044482707977,0,0,0,20,50.6419372558594,1,6,3,2.20962524414062,43.9882698059082,,,,,,,,,,,,,,,,
,3895750402.4555,49.9412574768066,-893.792694091797,3.50957160595598E-7,3.27926667795091E-7,1,0.499626677034896,40.0298881530762,1.99560566314186,17.7599992603064,4.25228692116735E-6,-2.33779613941621E-6,0.25,-2.8553137388158E-7,3.52494941750739E-7,-2.82448774506482E-7,49.9413261413574,49.9413261413574,-896.840942382813,-890.744445800781,51.9298355606593,20.3854330700063,0.994030714035034,0,0,0,20,50.6433296203613,1,6,3,2.23037719726562,43.49951171875,,,,,,,,,,,,,,,,
,3895750413.9435,49.9428367614746,-1008.31481933594,1.42295976322646E-6,3.85564165770346E-7,1,0.499626677034896,40.0298881530762,1.99559563941553,17.7599992603064,1.41317628235612E-5,7.57890431768727E-6,0.25,4.58905475315516E-7,1.41718944964042E-6,4.68717199545686E-7,49.9427719116211,49.9427719116211,-1010.76287841797,-1005.86676025391,52.2229462553709,20.3838823281982,0.993842124938965,0,0,0,20,50.6433753967285,1,6,3,2.23037719726562,42.5219955444336,,,,,,,,,,,,,,,,
,3895750425.428,49.9445114135742,-1123.24615478516,2.43679749748665E-6,3.60063288533542E-7,1,0.499626677034896,40.0298881530762,1.9954730794727,17.7599992603064,2.59672093552475E-5,3.27800386938117E-6,0.25,-1.33486323602403E-7,2.4337581964996E-6,-1.15159083289172E-7,49.9445114135742,49.9445114135742,-1125.79602050781,-1120.6962890625,51.986112814044,20.3864497125358,0.993813872337341,0,0,0,20,50.6455993652344,1,6,3,2.22396850585938,44.4770278930664,,,,,,,,,,,,,,,,
,3895750436.9225,49.9459228515625,-1238.25927734375,3.29887893146187E-6,3.62556566191958E-7,1,0.499626677034896,40.0298881530762,1.9956174182098,17.7599992603064,3.3510466722858E-5,1.34678573721328E-5,0.25,6.75059514669382E-7,3.28842073672154E-6,6.98458340421942E-7,49.9459228515625,49.9459228515625,-1240.78405761719,-1235.73449707031,52.3769270736594,20.3832264445303,0.993670165538788,0,0,0,20,50.650218963623,1,6,3,2.20779418945313,43.9882698059082,,,,,,,,,,,,,,,,
,3895750448.4145,49.9492149353027,-1353.11779785156,3.99706640149792E-6,2.66595422661622E-7,1,0.499626677034896,40.0298881530762,1.99550296273731,17.7599992603064,4.1524441593834E-5,1.12498092764659E-5,0.25,3.37641698414506E-7,3.98798455914506E-6,3.66787426632314E-7,49.9492149353027,49.9492149353027,-1355.62878417969,-1350.60681152344,51.7875791701593,20.3849952368774,0.993658006191254,0,0,0,20,50.6520652770996,1,6,3,2.21878051757813,43.49951171875,,,,,,,,,,,,,,,,
,3895750459.903,49.9499797821045,-1468.09429931641,5.39220540194113E-6,3.28991277440675E-7,1,0.499626677034896,40.0298881530762,1.99551160890435,17.7599992603064,5.6576312906505E-5,1.21171469680736E-5,0.25,1.65533216938678E-7,5.38213264912845E-6,2.05330219448246E-7,49.9500274658203,49.9500274658203,-1470.60046386719,-1465.58813476562,51.9040418195247,20.3855748557058,0.993757665157318,0,0,0,20,50.6518440246582,1,6,3,2.2186279296875,43.0107536315918,,,,,,,,,,,,,,,,
,3895750471.3945,49.9533920288086,-1582.62884521484,6.02682975959754E-6,3.76072583567562E-7,1,0.499626677034896,40.0298881530762,1.99557230194466,17.7599992603064,6.24119395530149E-5,1.80708465326389E-5,0.25,6.1405954537567E-7,6.01241589628002E-6,6.57840961625828E-7,49.953296661377,49.953296661377,-1584.62548828125,-1580.63220214844,52.0009637559094,20.384368640415,0.993438839912415,0,0,0,20,50.6539154052734,1,6,3,2.220458984375,44.9657897949219,,,,,,,,,,,,,,,,
,3895750482.8995,49.9540481567383,-1697.79266357422,7.8900218955305E-6,3.95641461235265E-7,1,0.499626677034896,40.0298881530762,1.99547179395962,17.7599992603064,8.25435198456643E-5,1.90451948455881E-5,0.25,3.66862245848279E-7,7.87443607185188E-6,4.24895631212934E-7,49.9540214538574,49.9540214538574,-1700.31311035156,-1695.27221679687,51.9110764761978,20.384650439553,0.993302881717682,0,0,0,20,50.6565437316895,1,6,3,2.21893310546875,42.5219955444336,,,,,,,,,,,,,,,,
,3895750494.367,49.957145690918,-1812.24444580078,8.77507264434348E-6,3.14312357884693E-7,1,0.499626677034896,40.0298881530762,1.9956004853237,17.7599992603064,9.11555686232659E-5,2.47671529227606E-5,0.25,7.4768434102233E-7,8.75526190689802E-6,8.11679158088663E-7,49.9570960998535,49.9570960998535,-1814.26098632813,-1810.22790527344,51.749279372717,20.3847087619835,0.993249297142029,0,0,0,20,50.6568603515625,1,6,3,2.2161865234375,44.9657897949219,,,,,,,,,,,,,,,,
,3895750505.857,49.9586963653564,-1927.10382080078,1.02693610040629E-5,3.02341292030629E-7,1,0.499626677034896,40.0298881530762,1.99554106370791,17.7599992603064,0.000107764181970212,2.30126884020149E-5,0.25,3.09090633859758E-7,1.02504335947925E-5,3.8490507683039E-7,49.9585342407227,49.9585342407227,-1929.02270507813,-1925.18493652344,51.5734129558901,20.3867795769287,0.993224740028381,0,0,0,20,50.6582450866699,1,6,3,2.22030639648438,43.9882698059082,,,,,,,,,,,,,,,,
,3895750517.363,49.9596328735352,-2042.70587158203,1.12557642753532E-5,3.76221155835423E-7,1,0.499626677034896,40.0298881530762,1.99561799147715,17.7599992603064,0.00011805535597091,2.55799273251653E-5,0.25,3.72492088650562E-7,1.12348234109119E-5,4.55537264076592E-7,49.9594421386719,49.9594421386719,-2045.208984375,-2040.20275878906,51.8868459921016,20.3869062776629,0.993053615093231,0,0,0,20,50.6610832214355,1,6,3,2.22488403320313,43.0107536315918,,,,,,,,,,,,,,,,
,3895750528.8505,49.9612522125244,-2156.6064453125,1.31402253503011E-5,4.38931847041197E-7,1,0.499626677034896,40.0298881530762,1.9955671679295,17.7599992603064,0.000137809777300395,2.99056989116094E-5,0.25,4.38996642174116E-7,1.31158146291821E-5,5.35942473094693E-7,49.961238861084,49.961238861084,-2159.14453125,-2154.068359375,51.8923173917363,20.3836967993788,0.992878317832947,0,0,0,20,50.6632080078125,1,6,3,2.21878051757813,44.9657897949219,,,,,,,,,,,,,,,,
,3895750540.362,49.9628372192383,-2272.03527832031,1.43724171022998E-5,3.06080271812E-7,1,0.499626677034896,40.0298881530762,1.9956380880746,17.7599992603064,0.000150231461666603,3.54927830456395E-5,0.25,7.43750245595364E-7,1.43438329713916E-5,8.4936821333469E-7,49.962833404541,49.962833404541,-2274.02416992187,-2270.04638671875,52.0142514407363,20.3857078372881,0.992688596248627,0,0,0,20,50.664436340332,1,6,3,2.23236083984375,45.4545478820801,,,,,,,,,,,,,,,,
,3895750551.82,49.9648036956787,-2386.64770507813,1.55593763768483E-5,3.15806668910946E-7,1,0.499626677034896,40.0298881530762,1.99564066752691,17.7599992603064,0.00016313798367412,3.56896606584842E-5,0.25,5.460287447932E-7,1.55304401925954E-5,6.60789677967655E-7,49.9648132324219,49.9648132324219,-2389.13793945313,-2384.15747070313,52.1307140901017,20.3850523055497,0.992571115493774,0,0,0,20,50.666259765625,1,6,3,2.21847534179687,43.49951171875,,,,,,,,,,,,,,,,
,3895750563.3335,49.9660339355469,-2502.16845703125,1.67728291476749E-5,2.98171930115023E-7,1,0.499626677034896,40.0298881530762,1.99552032268218,17.7599992603064,0.00017460310552319,4.53205819652712E-5,0.25,1.23774758120985E-6,1.67368986230721E-5,1.36042882799497E-6,49.9659423828125,49.9659423828125,-2504.13525390625,-2500.20166015625,52.2080953135055,20.384764373639,0.992531657218933,0,0,0,20,50.6653099060059,1,6,3,2.22137451171875,43.49951171875,,,,,,,,,,,,,,,,
,3895750574.811,49.9682121276855,-2616.72387695313,1.89042577451582E-5,3.65883993070383E-7,1,0.499626677034896,40.0298881530762,1.99552815080906,17.7599992603064,0.000198063592847763,4.4108649629498E-5,0.25,7.34341440421777E-7,1.88687747558368E-5,8.73671624190116E-7,49.9682121276855,49.9682121276855,-2619.2900390625,-2614.15771484375,51.7813261420055,20.384288326669,0.992466390132904,0,0,0,20,50.6674766540527,1,6,3,2.21115112304687,43.9882698059082,,,,,,,,,,,,,,,,
,3895750586.3135,49.9687252044678,-2731.59936523438,1.97365897338769E-5,3.58656537862274E-7,1,0.499626677034896,40.0298881530762,1.99551085078656,17.7599992603064,0.000207322448054619,4.30933346632444E-5,0.25,4.86417553903384E-7,1.97017259510515E-5,6.32331737497408E-7,49.9688148498535,49.9688148498535,-2734.10961914062,-2729.08911132813,52.1213345478709,20.3864300880437,0.992394983768463,0,0,0,20,50.6672859191895,1,6,3,2.23052978515625,43.9882698059082,,,,,,,,,,,,,,,,
touchdown = 11.7699997499585 mm,3895750620.9955,49.9728927612305,-3000.29223632812,2.34131371096868E-5,3.55530779945041E-7,1,0.499626677034896,40.0298881530762,1.9840386237493,17.7599992603064,0.000244415024593758,5.18015375414691E-5,0.25,6.68680690566129E-7,2.3371396260049E-5,8.41644699490377E-7,49.9728927612305,49.9728927612305,-3000.29223632812,-3000.29223632812,51.5022847606401,20.3843030076451,0.99191415309906,0,0,0,20,50.6723098754883,1,4,3,2.19924926757813,42.0332374572754,,,,,,,,,,,,,,,,
,3895750638.2565,49.9742317199707,-2899.45239257812,2.25075612805248E-5,3.05945375540089E-7,1,0.499626677034896,40.0298881530762,1.9839921817978,17.7599992603064,0.000234739922874706,5.09783390101028E-5,0.25,7.55429957600305E-7,2.24665099927849E-5,9.21522700534182E-7,49.9742317199707,49.9742317199707,-2902.4921875,-2896.41259765625,52.0345737822363,20.3851906790856,0.991768419742584,0,0,0,20,50.6734771728516,1,6,3,2.21084594726562,41.5444793701172,,,,,,,,,,,,,,,,
,3895750649.7545,49.9746398925781,-2783.95104980469,2.02534606518152E-5,3.4226208413397E-7,1,0.499626677034896,40.0298881530762,1.98408138700724,17.7599992603064,0.000210638172354229,4.91717037578539E-5,0.25,9.93957357156768E-7,2.02140885308746E-5,1.14291497248833E-6,49.9745483398438,49.9745483398438,-2786.41552734375,-2781.48657226562,52.3480068184478,20.385797898751,0.991669595241547,0,0,0,20,50.6746711730957,1,6,3,2.20550537109375,42.0332374572754,,,,,,,,,,,,,,,,
,3895750661.2545,49.9755764007568,-2668.99060058594,1.86647017340514E-5,2.75111226266389E-7,1,0.499626677034896,40.0298881530762,1.98406862047761,17.7599992603064,0.000195388608654438,3.83148556363676E-5,0.25,2.49013781358969E-7,1.86332899542067E-5,3.873371701747E-7,49.9754219055176,49.9754219055176,-2671.51293945313,-2666.46826171875,51.8759031928324,20.3855272512301,0.991488695144653,0,0,0,20,50.6738319396973,1,6,3,2.20962524414062,42.0332374572754,,,,,,,,,,,,,,,,
,3895750672.7545,49.975133895874,-2554.49145507813,1.74313973462065E-5,4.23772786711661E-7,1,0.499626677034896,40.0298881530762,1.98399087760213,17.7599992603064,0.000181615815140535,4.04688288043879E-5,0.25,6.7924240976293E-7,1.73986553513889E-5,8.07713356454128E-7,49.9748306274414,49.9748306274414,-2556.4892578125,-2552.49365234375,51.8055566261016,20.3860677533572,0.991367816925049,0,0,0,20,50.6766319274902,1,6,3,2.20413208007813,42.5219955444336,,,,,,,,,,,,,,,,
,3895750684.2195,49.9787616729736,-2439.85852050781,1.5657371433235E-5,3.91484383092096E-7,1,0.499626677034896,40.0298881530762,1.98399357490555,17.7599992603064,0.000163983732393899,3.16777149881358E-5,0.25,1.64841023912331E-7,1.56312140148826E-5,2.80942939992791E-7,49.9787712097168,49.9787712097168,-2442.29541015625,-2437.42163085938,52.033792153717,20.3862279488902,0.991409659385681,0,0,0,20,50.6768646240234,1,6,3,2.21694946289062,43.9882698059082,,,,,,,,,,,,,,,,
,3895750695.723,49.9785327911377,-2324.83410644531,1.42575107430769E-5,3.0805723086317E-7,1,0.499626677034896,40.0298881530762,1.98396881578476,17.7599992603064,0.000148522700340053,3.32198212693751E-5,0.25,5.67017468219356E-7,1.42305249355946E-5,6.72071181094195E-7,49.9786529541016,49.9786529541016,-2327.28271484375,-2322.38549804687,51.922019275467,20.3869821444916,0.991344928741455,0,0,0,20,50.6783981323242,1,6,3,2.20504760742187,44.4770278930664,,,,,,,,,,,,,,,,
,3895750707.2015,49.9783229827881,-2209.88903808594,1.27390557572861E-5,2.66029681103634E-7,1,0.499626677034896,40.0298881530762,1.98397068129355,17.7599992603064,0.000133935228019131,2.29281552356869E-5,0.25,-1.36985401427739E-7,1.27196665944469E-5,-4.20927881814468E-8,49.9781227111816,49.9781227111816,-2212.32788085938,-2207.4501953125,52.5527934904863,20.3873642884312,0.991100907325745,0,0,0,20,50.6794700622559,1,6,3,2.21237182617187,44.4770278930664,,,,,,,,,,,,,,,,
,3895750718.706,49.9776287078857,-2094.90454101562,1.13280585107218E-5,3.7431846674093E-7,1,0.499626677034896,40.0298881530762,1.98386550307494,17.7599992603064,0.000118114958209154,2.57571125686471E-5,0.25,3.89944232962309E-7,1.13069586073494E-5,4.73503495827738E-7,49.9776229858398,49.9776229858398,-2097.4091796875,-2092.39990234375,52.4105370999863,20.3820858487201,0.991033256053925,0,0,0,20,50.6795883178711,1,6,3,2.21511840820313,42.0332374572754,,,,,,,,,,,,,,,,
,3895750730.199,49.9818878173828,-1980.06719970703,1.01376249681733E-5,2.60152197828015E-7,1,0.499626677034896,40.0298881530762,1.98389742064192,17.7599992603064,0.000106448824807134,1.89637551001445E-5,0.25,-4.0531482521724E-8,1.01216039072983E-5,3.48720225460989E-8,49.9820365905762,49.9820365905762,-1982.54943847656,-1977.5849609375,52.0947591782171,20.3877392525883,0.990941941738129,0,0,0,20,50.6824684143066,1,6,3,2.20993041992187,43.0107536315918,,,,,,,,,,,,,,,,
,3895750741.6945,49.9815711975098,-1865.05499267578,8.1366445669442E-6,2.55405342083143E-7,1,0.499626677034896,40.0298881530762,1.9839195411911,17.7599992603064,8.56209405290019E-5,1.42187755689753E-5,0.25,-1.28022560932794E-7,8.12445757055261E-6,-6.73488389612025E-8,49.9817237854004,49.9817237854004,-1867.52014160156,-1862.58984375,51.8196259394478,20.3845562270872,0.990878045558929,0,0,0,20,50.6804313659668,1,6,3,2.20733642578125,42.5219955444336,,,,,,,,,,,,,,,,
,3895750753.2045,49.9825649261475,-1750.021484375,7.07527713365834E-6,2.27695135281572E-7,1,0.499626677034896,40.0298881530762,1.9839269392907,17.7599992603064,7.52913556586338E-5,7.76056961641454E-6,0.25,-5.50048841776089E-7,7.06791053208435E-6,-4.96579545753915E-7,49.9824562072754,49.9824562072754,-1752.49243164062,-1747.55053710938,52.0087800411017,20.3866235799417,0.990792095661163,0,0,0,20,50.6820182800293,1,6,3,2.21115112304687,42.5219955444336,,,,,,,,,,,,,,,,
,3895750764.6925,49.9822959899902,-1635.82269287109,5.19074265332525E-6,2.86092767447289E-7,1,0.499626677034896,40.0298881530762,1.98390849637381,17.7599992603064,5.44143394185972E-5,1.02033607375436E-5,0.25,2.62784075387039E-8,5.18212072419282E-6,6.48093823573673E-8,49.9823837280273,49.9823837280273,-1638.8427734375,-1632.80261230469,51.8211891964863,20.3883824950558,0.990521252155304,0,0,0,20,50.6828079223633,1,6,3,2.20626831054687,44.4770278930664,,,,,,,,,,,,,,,,
,3895750776.162,49.9837608337402,-1520.22937011719,4.36075752849837E-6,2.43176297059991E-7,1,0.499626677034896,40.0298881530762,1.98387281687205,17.7599992603064,4.64139140164349E-5,4.72455463519127E-6,0.25,-3.44581766273086E-7,4.35622171204575E-6,-3.11615614953138E-7,49.9839668273926,49.9839668273926,-1522.75415039062,-1517.70458984375,51.6586104644862,20.3841963765326,0.99049699306488,0,0,0,20,50.6828727722168,1,6,3,2.20962524414062,42.5219955444336,,,,,,,,,,,,,,,,
,3895750787.6765,49.9840221405029,-1405.37951660156,2.80156176154081E-6,1.75573382523054E-7,1,0.499626677034896,40.0298881530762,1.9838964077968,17.7599992603064,3.08704404134896E-5,-2.7343956391454E-6,0.25,-7.71264133542907E-7,2.80272209731784E-6,-7.49187259947002E-7,49.9840126037598,49.9840126037598,-1407.85461425781,-1402.90441894531,52.1314957186209,20.3863856481386,0.990506589412689,0,0,0,20,50.6832847595215,1,6,3,2.20657348632813,44.9657897949219,,,,,,,,,,,,,,,,
,3895750799.169,49.9850292205811,-1291.31585693359,1.87852134379761E-6,2.58072309250127E-7,1,0.499626677034896,40.0298881530762,1.98393301770073,17.7599992603064,2.1063082390325E-5,-3.82690744418736E-6,0.25,-7.0713345267157E-7,1.88070373573796E-6,-6.92017787752347E-7,49.9848823547363,49.9848823547363,-1293.8017578125,-1288.82995605469,51.7141060893516,20.3847733707383,0.990380048751831,0,0,0,20,50.6839599609375,1,6,3,2.21145629882813,44.9657897949219,,,,,,,,,,,,,,,,
,3895750810.6295,49.9852542877197,-1176.48284912109,6.57568003985882E-7,3.04809086600091E-7,1,0.499626677034896,40.0298881530762,1.98398450072404,17.7599992603064,7.82934931924928E-6,-3.84218322737388E-6,0.25,-4.86030487545839E-7,6.60101481633193E-7,-4.80347331530558E-7,49.9852333068848,49.9852333068848,-1179.00634765625,-1173.95935058594,51.7758547423709,20.3883985884936,0.990227818489075,0,0,0,20,50.6842651367188,1,6,3,2.21755981445313,43.9882698059082,,,,,,,,,,,,,,,,
,3895750822.127,49.9860439300537,-1060.85809326172,-5.82449752510915E-7,2.37765105699688E-7,1,0.499626677034896,40.0298881530762,1.9838671008233,17.7599992603064,-5.93957254457273E-6,-2.05545727353754E-6,0.25,-8.973613572617E-8,-5.80825724186824E-7,-9.39166821865845E-8,49.9861030578613,49.9861030578613,-1062.94152832031,-1058.77465820312,52.0158146977747,20.3843550501273,0.990077555179596,0,0,0,20,50.6866035461426,1,6,3,2.2064208984375,43.49951171875,,,,,,,,,,,,,,,,
,3895750833.617,49.9864807128906,-946.450073242188,-1.62265149807835E-6,2.71637462765894E-7,1,0.499626677034896,40.0298881530762,1.98388919064561,17.7599992603064,-1.53529033067176E-5,-1.22785666979963E-5,0.25,-8.7447538297422E-7,-1.61348061400361E-6,-8.85092164770758E-7,49.9865684509277,49.9865684509277,-948.977966308594,-943.922180175781,52.4457103833517,20.3866944998358,0.989948987960815,0,0,0,20,50.6861724853516,1,6,3,2.21145629882813,44.9657897949219,,,,,,,,,,,,,,,,
,3895750845.1105,49.9874687194824,-831.281005859375,-2.54452984241145E-6,3.8094417411642E-7,1,0.499626677034896,40.0298881530762,1.9839474050058,17.7599992603064,-2.53778691618615E-5,-1.21123235285095E-5,0.25,-6.90566357304982E-7,-2.53519778519996E-6,-7.08333469269372E-7,49.9874687194824,49.9874687194824,-833.825439453125,-828.736572265625,51.7195774889862,20.387057684909,0.989875495433807,0,0,0,20,50.6868324279785,1,6,3,2.2100830078125,42.5219955444336,,,,,,,,,,,,,,,,
,3895750856.6065,49.9869499206543,-715.709289550781,-3.56990812086638E-6,3.81196622386645E-7,1,0.499626677034896,40.0298881530762,1.98392516000888,17.7599992603064,-3.55936476632439E-5,-1.70495687039771E-5,0.25,-9.74236212895E-7,-3.55676129401751E-6,-9.99149809086553E-7,49.9866256713867,49.9866256713867,-717.711303710937,-713.707275390625,52.1580710882748,20.3877206526175,0.990048825740814,0,0,0,20,50.6869812011719,1,6,3,2.22000122070313,44.9657897949219,,,,,,,,,,,,,,,,
,3895750868.1065,49.9894618988037,-601.404174804687,-3.94014729196701E-6,3.3113769905877E-7,1,0.499626677034896,40.0298881530762,1.98388651837052,17.7599992603064,-3.85570823995403E-5,-2.28068134307231E-5,0.25,-1.45550395856154E-6,-3.92280051820783E-6,-1.4823676163231E-6,49.989444732666,49.989444732666,-603.921936035156,-598.886413574219,51.9853311855247,20.3869711016922,0.989860117435455,0,0,0,20,50.6878776550293,1,6,3,2.20977783203125,45.4545478820801,,,,,,,,,,,,,,,,
,3895750879.64,49.988697052002,-485.770690917969,-4.56040745472853E-6,3.05296962426196E-7,1,0.499626677034896,40.0298881530762,1.9839728089284,17.7599992603064,-4.63391459551273E-5,-1.70128900549608E-5,0.25,-7.90170236739069E-7,-4.54695875845481E-6,-8.22742084154251E-7,49.988697052002,49.988697052002,-487.772277832031,-483.769104003906,51.9071683336016,20.3845152994921,0.989796221256256,0,0,0,20,50.6845474243164,1,6,3,2.2064208984375,44.4770278930664,,,,,,,,,,,,,,,,
,3895750891.076,49.9890251159668,-371.856307983398,-4.53594562886828E-6,3.07914814337919E-7,1,0.499626677034896,40.0298881530762,1.98393402681891,17.7599992603064,-4.65384275643381E-5,-1.44587502605856E-5,0.25,-5.51235957218176E-7,-4.52429819842225E-6,-5.84020829104305E-7,49.9890251159668,49.9890251159668,-373.818298339844,-369.894317626953,52.2737521091209,20.3870359951743,0.989593327045441,0,0,0,20,50.6880989074707,1,6,3,2.21939086914062,43.9882698059082,,,,,,,,,,,,,,,,
,3895750902.568,49.9904022216797,-256.30396270752,-4.43509576175543E-6,3.06137813357664E-7,1,0.499626677034896,40.0298881530762,1.98401455592055,17.7599992603064,-4.49604281878588E-5,-1.71274022554391E-5,0.25,-8.23902686027923E-7,-4.42157808511031E-6,-8.55481635051481E-7,49.990104675293,49.990104675293,-258.777099609375,-253.830825805664,52.0173779548132,20.3885203950491,0.989375352859497,0,0,0,20,50.6881332397461,1,6,3,2.20809936523438,42.5219955444336,,,,,,,,,,,,,,,,
,3895750914.06,49.9895076751709,-141.872360229492,-4.37858757478988E-6,4.29564766427327E-7,1,0.499626677034896,40.0298881530762,1.98395563489525,17.7599992603064,-4.36131066669239E-5,-2.11498531115951E-5,0.25,-1.21762339581658E-6,-4.36222499754768E-6,-1.24812162291077E-6,49.9893455505371,49.9893455505371,-143.828674316406,-139.916046142578,52.2041871709094,20.3873513238619,0.989395916461945,0,0,0,20,50.6861038208008,1,6,3,2.20977783203125,43.0107536315918,,,,,,,,,,,,,,,,
,3895750925.541,49.991771697998,-26.3697052001953,-3.55563767798595E-6,5.02323733038878E-7,1,0.499626677034896,40.0298881530762,1.98393573331378,17.7599992603064,-3.47077704943612E-5,-2.10582906321025E-5,0.25,-1.35892354729614E-6,-3.5395942136471E-6,-1.38306871478341E-6,49.991771697998,49.991771697998,-28.8956394195557,-23.843770980835,52.1674506305055,20.3859727691041,0.989191472530365,0,0,0,20,50.689826965332,1,6,3,2.20474243164062,43.9882698059082,,,,,,,,,,,,,,,,
,3895750937.0395,49.9913864135742,88.0675849914551,-2.19187483761897E-6,2.74688503648543E-7,1,0.499626677034896,40.0298881530762,1.98398776742402,17.7599992603064,-2.15453995738131E-5,-1.2163119892329E-5,0.25,-7.59690290776601E-7,-2.18256686105885E-6,-7.74705977845083E-7,49.9913864135742,49.9913864135742,85.014762878418,91.1204071044922,52.2987642217363,20.3838295897399,0.989271879196167,0,0,0,20,50.6876068115234,1,6,3,2.20947265625,43.0107536315918,,,,,,,,,,,,,,,,
,3895750948.538,49.9918212890625,202.565872192383,-1.28599494577181E-6,2.70242400108943E-7,1,0.499626677034896,40.0298881530762,1.98398899801801,17.7599992603064,-1.04387670278191E-5,-1.92178185678642E-5,0.25,-1.59715761827944E-6,-1.27198228481758E-6,-1.60404759523839E-6,49.9916191101074,49.9916191101074,200.026031494141,205.105712890625,52.1041387204478,20.3865047757479,0.98905211687088,0,0,0,20,50.6889305114746,1,6,3,2.20687866210938,44.9657897949219,,,,,,,,,,,,,,,,
,3895750960.029,49.9910564422607,317.512054443359,-5.92468787339575E-7,3.38829295258649E-7,1,0.499626677034896,40.0298881530762,1.98396028500528,17.7599992603064,-3.61802232421867E-6,-1.53886022046549E-5,0.25,-1.35864156007873E-6,-5.81387056646676E-7,-1.36078050288542E-6,49.9913597106934,49.9913597106934,315.069152832031,319.954956054687,51.8383850239093,20.3862895698078,0.98903501033783,0,0,0,20,50.6878814697266,1,6,3,2.216796875,43.49951171875,,,,,,,,,,,,,,,,
,3895750971.5125,49.9915752410889,432.467788696289,-1.24615457444647E-7,2.45830268534777E-7,1,0.499626677034896,40.0298881530762,1.98400403638746,17.7599992603064,1.00869685341876E-6,-1.29457242620603E-5,0.25,-1.21106735285539E-6,-1.15409848153361E-7,-1.20998013194423E-6,49.9916610717773,49.9916610717773,430.000885009766,434.934692382812,51.7281754026978,20.3888591775726,0.988768935203552,0,0,0,20,50.6894454956055,1,6,3,2.2088623046875,43.0107536315918,,,,,,,,,,,,,,,,
,3895750982.9975,49.9924907684326,547.462493896484,-4.73264865916431E-8,2.5393477448865E-7,1,0.499626677034896,40.0298881530762,1.98401497707806,17.7599992603064,2.22498599859038E-6,-1.50215708947841E-5,0.25,-1.42297919681485E-6,-3.66748290177431E-8,-1.42097081599517E-6,49.9925422668457,49.9925422668457,544.968872070313,549.956115722656,52.0095616696209,20.3873277615959,0.988893210887909,0,0,0,20,50.6901931762695,1,6,3,2.20977783203125,44.9657897949219,,,,,,,,,,,,,,,,
,3895750994.554,49.9934558868408,662.883941650391,-3.00332953018754E-7,3.29681401779745E-7,1,0.499626677034896,40.0298881530762,1.98395772139244,17.7599992603064,6.36404903910616E-7,-2.13542306632952E-5,0.25,-1.98043399755285E-6,-2.85120583424997E-7,-1.97938883679839E-6,49.9934005737305,49.9934005737305,659.912414550781,665.85546875,51.7125428323132,20.3865943763216,0.988702416419983,0,0,0,20,50.6911125183105,1,6,3,2.2100830078125,44.4770278930664,,,,,,,,,,,,,,,,
,3895751006.0295,49.9923706054687,778.171936035156,-5.57627755974886E-7,2.73346824709692E-7,1,0.499626677034896,40.0298881530762,1.9839933443802,17.7599992603064,-3.36948711318312E-6,-1.46808942111072E-5,0.25,-1.297500111737E-6,-5.47065942739862E-7,-1.29950121582638E-6,49.992431640625,49.992431640625,776.276977539063,780.06689453125,52.1940260001594,20.3878702846074,0.988627314567566,0,0,0,20,50.6904335021973,1,6,3,2.20901489257813,43.49951171875,,,,,,,,,,,,,,,,
,3895751017.4795,49.9930801391602,892.665802001953,-1.81995778268977E-6,3.22853900288276E-7,1,0.499626677034896,40.0298881530762,1.98393546662556,17.7599992603064,-1.61567445326748E-5,-1.96058019719563E-5,0.25,-1.53681342156434E-6,-1.8055407061712E-6,-1.54780561334309E-6,49.9928894042969,49.9928894042969,890.126281738281,895.205322265625,51.840729909467,20.3870095234676,0.988568007946014,0,0,0,20,50.6911735534668,1,6,3,2.208251953125,43.9882698059082,,,,,,,,,,,,,,,,
,3895751028.973,49.9940738677978,1007.11010742187,-2.26414738850363E-6,2.81702375758306E-7,1,0.499626677034896,40.0298881530762,1.98392942223181,17.7599992603064,-2.03531376859895E-5,-2.30026237837391E-5,0.25,-1.77958222390747E-6,-2.24720421886476E-6,-1.79348301110386E-6,49.9943237304687,49.9943237304687,1005.10363769531,1009.11657714844,51.9165478758324,20.3874490256224,0.988614022731781,0,0,0,20,50.6903991699219,1,6,3,2.21817016601562,43.49951171875,,,,,,,,,,,,,,,,
,3895751040.471,49.9938068389893,1122.50964355469,-3.50279792199726E-6,4.59345050393145E-7,1,0.499626677034896,40.0298881530762,1.98404322813765,17.7599992603064,-3.45230651334304E-5,-1.89467776330416E-5,0.25,-1.16715310869698E-6,-3.48838453527099E-6,-1.19126911512329E-6,49.9939842224121,49.9939842224121,1120.02001953125,1124.99926757812,52.1127366341594,20.3869437608364,0.988296031951904,0,0,0,20,50.6908340454102,1,6,3,2.21664428710938,44.9657897949219,,,,,,,,,,,,,,,,
,3895751051.969,49.9934425354004,1237.53186035156,-4.51687781295238E-6,4.23292999631706E-7,1,0.499626677034896,40.0298881530762,1.98393438603278,17.7599992603064,-4.45833961869611E-5,-2.40584366322712E-5,0.25,-1.46956313590087E-6,-4.4985733989389E-6,-1.50072541011026E-6,49.9934425354004,49.9934425354004,1235.12536621094,1239.93835449219,52.2878214224671,20.3857099333821,0.988226354122162,0,0,0,20,50.6911010742188,1,6,3,2.216796875,44.4770278930664,,,,,,,,,,,,,,,,
,3895751063.4395,49.9936656951904,1351.90014648438,-4.93876355608692E-6,4.39640985367068E-7,1,0.499626677034896,40.0298881530762,1.98401539731039,17.7599992603064,-4.85895721984221E-5,-2.71851384757146E-5,0.25,-1.69054002534348E-6,-4.91814823939608E-6,-1.7244838023689E-6,49.9936065673828,49.9936065673828,1349.857421875,1353.94287109375,51.6445411511401,20.3891687782385,0.988178253173828,0,0,0,20,50.6911201477051,1,6,3,2.20993041992187,44.4770278930664,,,,,,,,,,,,,,,,
,3895751074.9345,49.9930515289307,1466.87329101562,-6.49210483770267E-6,3.11737646988918E-7,1,0.499626677034896,40.0298881530762,1.98390961195095,17.7599992603064,-6.46658798770983E-5,-3.13617672263267E-5,0.25,-1.8055777560251E-6,-6.4681282693206E-6,-1.85088498312279E-6,49.9928550720215,49.9928550720215,1464.90026855469,1468.84631347656,52.1416568893709,20.3881134186587,0.987911403179169,0,0,0,20,50.6923789978027,1,6,3,2.20993041992187,44.4770278930664,,,,,,,,,,,,,,,,
,3895751086.4275,49.9949798583984,1581.60064697266,-7.44641157314046E-6,3.83942080306813E-7,1,0.499626677034896,40.0298881530762,1.98385252022308,17.7599992603064,-7.44322531340597E-5,-3.45308796028105E-5,0.25,-1.93373645692255E-6,-7.4199670931206E-6,-1.98593730939478E-6,49.9949798583984,49.9949798583984,1578.57385253906,1584.62744140625,52.0658389230055,20.3885095327683,0.987930297851562,0,0,0,20,50.693473815918,1,6,3,2.20809936523438,43.49951171875,,,,,,,,,,,,,,,,
,3895751097.9285,49.9939727783203,1696.08172607422,-8.86579644443577E-6,4.23846516763984E-7,1,0.499626677034896,40.0298881530762,1.9838863102596,17.7599992603064,-9.01613945285761E-5,-3.2667499382075E-5,0.25,-1.49735767235824E-6,-8.84032927431912E-6,-1.56082092218852E-6,49.9942359924316,49.9942359924316,1693.66052246094,1698.5029296875,51.942341616967,20.3889512041026,0.987872302532196,0,0,0,20,50.6926536560059,1,6,3,2.20596313476562,43.49951171875,,,,,,,,,,,,,,,,
,3895751109.451,49.9953861236572,1811.54876708984,-1.01531924156523E-5,3.8846605808145E-7,1,0.499626677034896,40.0298881530762,1.98387309370962,17.7599992603064,-0.00010288789189357,-3.94169348107734E-5,0.25,-1.90595712686035E-6,-1.01226563497498E-5,-1.97833718231858E-6,49.9952201843262,49.9952201843262,1809.59631347656,1813.50122070313,52.1479099175247,20.3878846712166,0.987719357013702,0,0,0,20,50.6926193237305,1,6,3,2.20748901367187,45.4545478820801,,,,,,,,,,,,,,,,
,3895751120.8965,49.9960899353027,1925.99139404297,-1.13435508310501E-5,4.95143475383916E-7,1,0.499626677034896,40.0298881530762,1.98385310610443,17.7599992603064,-0.000115380415850999,-4.16759693798192E-5,0.25,-1.90429942216417E-6,-1.13111609860046E-5,-1.98553848780622E-6,49.9960670471191,49.9960670471191,1923.49609375,1928.48669433594,51.7610038005055,20.3868650959452,0.987633466720581,0,0,0,20,50.6929206848145,1,6,3,2.20733642578125,44.9657897949219,,,,,,,,,,,,,,,,
,3895751132.396,49.9948921203613,2040.97735595703,-1.29861287000164E-5,2.99484768104269E-7,1,0.499626677034896,40.0298881530762,1.98391796984619,17.7599992603064,-0.000132654002168856,-4.46320770187109E-5,0.25,-1.88647785418892E-6,-1.29512847605316E-5,-1.97996166882106E-6,49.9948921203613,49.9948921203613,2038.46154785156,2043.4931640625,52.5129304360056,20.3879722882837,0.987625181674957,0,0,0,20,50.6927719116211,1,6,3,2.20687866210938,44.4770278930664,,,,,,,,,,,,,,,,
,3895751143.8885,49.9941635131836,2155.98767089844,-1.39264107972132E-5,3.63834580988243E-7,1,0.499626677034896,40.0298881530762,1.98397916172042,17.7599992603064,-0.000141788930527711,-5.04709379842809E-5,0.25,-2.27138014052533E-6,-1.38872595797352E-5,-2.37124591199793E-6,49.9941062927246,49.9941062927246,2153.546875,2158.42846679687,52.2471767394671,20.3891794302051,0.987372815608978,0,0,0,20,50.6935272216797,1,6,3,2.21084594726562,44.4770278930664,,,,,,,,,,,,,,,,
,3895751155.381,49.9968795776367,2270.94982910156,-1.49313472470494E-5,3.10787183852796E-7,1,0.499626677034896,40.0298881530762,1.98394909573881,17.7599992603064,-0.000153422048316161,-4.64157628828848E-5,0.25,-1.70178649281514E-6,-1.48949042268947E-5,-1.81004271104124E-6,49.9968795776367,49.9968795776367,2268.4970703125,2273.40258789062,52.1635424879094,20.388473767477,0.98726087808609,0,0,0,20,50.6937255859375,1,6,3,2.20779418945313,43.0107536315918,,,,,,,,,,,,,,,,
,3895751166.88,49.9959506988525,2386.19812011719,-1.66375575725921E-5,4.39378026016997E-7,1,0.499626677034896,40.0298881530762,1.98392757064686,17.7599992603064,-0.000170939989228155,-5.17886918638988E-5,0.25,-1.90285288712873E-6,-1.65969747417557E-5,-2.02347896944547E-6,49.9959373474121,49.9959373474121,2383.71484375,2388.68139648438,52.270625595044,20.3879573867272,0.987165093421936,0,0,0,20,50.6948890686035,1,6,3,2.20458984375,43.49951171875,,,,,,,,,,,,,,,,
,3895751178.377,49.9970474243164,2500.62707519531,-1.80231696489293E-5,4.44126020157348E-7,1,0.499626677034896,40.0298881530762,1.98398963578171,17.7599992603064,-0.000184934042453829,-5.74681256543105E-5,0.25,-2.19134842385882E-6,-1.79783319292242E-5,-2.32182676701296E-6,49.9971008300781,49.9971008300781,2498.59692382813,2502.6572265625,52.0423900674286,20.3897758473502,0.987158477306366,0,0,0,20,50.6930465698242,1,6,3,2.21664428710938,45.4545478820801,,,,,,,,,,,,,,,,
,3895751189.842,49.9968299865723,2615.07470703125,-1.98883775537897E-5,4.55572107714137E-7,1,0.499626677034896,40.0298881530762,1.98397350786262,17.7599992603064,-0.000205039453455487,-5.81084246959366E-5,0.25,-1.91239815348121E-6,-1.98427516923651E-5,-2.05719153276725E-6,49.9968299865723,49.9968299865723,2612.55908203125,2617.59033203125,52.189336229044,20.3870107499267,0.986856818199158,0,0,0,20,50.6925354003906,1,6,3,2.20779418945313,43.9882698059082,,,,,,,,,,,,,,,,
,3895751201.341,49.9967021942139,2731.08679199219,-2.13694521442222E-5,4.05247336206911E-7,1,0.499626677034896,40.0298881530762,1.98402290182904,17.7599992603064,-0.000220335940491243,-6.23222792606607E-5,0.25,-2.04383075867293E-6,-2.13206134293787E-5,-2.19943590952023E-6,49.996524810791,49.996524810791,2728.6240234375,2733.54956054687,51.7375549449286,20.3897419688274,0.98685097694397,0,0,0,20,50.6930809020996,1,6,3,2.20733642578125,44.4770278930664,,,,,,,,,,,,,,,,
touchdown = 11.8000004440546 mm,3895751236.3255,49.9976043701172,3000.2373046875,-2.51892583930067E-5,3.66531229253092E-7,1,0.499626677034896,40.0298881530762,1.98393134576913,17.790000885725,-0.000259547036615629,-7.43690165031354E-5,0.25,-2.49578722754784E-6,-2.51313413497334E-5,-2.6791048523158E-6,49.9976043701172,49.9976043701172,3000.2373046875,3000.2373046875,51.7101979467555,20.3840108529851,0.986469388008118,0,0,0,20,50.6925621032715,1,4,3,2.2064208984375,41.5444793701172,,,,,,,,,,,,,,,,